I'm sorry, but an uncaught exception occurred.

While running game code:
  File "game/script.rpy", line 238, in script call
    call battle(tonysoprano)
  File "game/script.rpy", line 562, in script
    $ enemy.hide_image()
  File "game/script.rpy", line 562, in <module>
    $ enemy.hide_image()
  File "game/enemy.rpy", line 13, in hide_image
    renpy.hide(self.image, at_list=[self.transform])
TypeError: hide() got an unexpected keyword argument 'at_list'

-- Full Traceback ------------------------------------------------------------

Full traceback:
  File "game/script.rpy", line 238, in script call
    call battle(tonysoprano)
  File "game/script.rpy", line 562, in script
    $ enemy.hide_image()
  File "C:\Users\Vile\Downloads\renpy-8.1.3-sdk\renpy\ast.py", line 1138, in execute
    renpy.python.py_exec_bytecode(self.code.bytecode, self.hide, store=self.store)
  File "C:\Users\Vile\Downloads\renpy-8.1.3-sdk\renpy\python.py", line 1122, in py_exec_bytecode
    exec(bytecode, globals, locals)
  File "game/script.rpy", line 562, in <module>
    $ enemy.hide_image()
  File "game/enemy.rpy", line 13, in hide_image
    renpy.hide(self.image, at_list=[self.transform])
TypeError: hide() got an unexpected keyword argument 'at_list'

Windows-10-10.0.19045 AMD64
Ren'Py 8.1.3.23091805
Derleth Manor 1.0
Fri Mar  8 11:18:11 2024
